[
  {
    "url": "https://api.github.com/repos/electron/electron/issues/comments/266807027",
    "html_url": "https://github.com/electron/electron/issues/8099#issuecomment-266807027",
    "issue_url": "https://api.github.com/repos/electron/electron/issues/8099",
    "id": 266807027,
    "user": {
      "login": "kevinsawicki",
      "id": 671378,
      "avatar_url": "https://avatars0.githubusercontent.com/u/671378?v=3",
      "gravatar_id": "",
      "url": "https://api.github.com/users/kevinsawicki",
      "html_url": "https://github.com/kevinsawicki",
      "followers_url": "https://api.github.com/users/kevinsawicki/followers",
      "following_url": "https://api.github.com/users/kevinsawicki/following{/other_user}",
      "gists_url": "https://api.github.com/users/kevinsawicki/gists{/gist_id}",
      "starred_url": "https://api.github.com/users/kevinsawicki/starred{/owner}{/repo}",
      "subscriptions_url": "https://api.github.com/users/kevinsawicki/subscriptions",
      "organizations_url": "https://api.github.com/users/kevinsawicki/orgs",
      "repos_url": "https://api.github.com/users/kevinsawicki/repos",
      "events_url": "https://api.github.com/users/kevinsawicki/events{/privacy}",
      "received_events_url": "https://api.github.com/users/kevinsawicki/received_events",
      "type": "User",
      "site_admin": true
    },
    "created_at": "2016-12-13T17:38:27Z",
    "updated_at": "2016-12-13T17:38:27Z",
    "body": "Do you know if `remote.autoUpdater.setFeedURL` is throwing an exception? Do you get any errors logged when running it directly from the dev tools Console?\r\n\r\nIs the `'after'` never logged or just eventually logged?"
  },
  {
    "url": "https://api.github.com/repos/electron/electron/issues/comments/266813181",
    "html_url": "https://github.com/electron/electron/issues/8099#issuecomment-266813181",
    "issue_url": "https://api.github.com/repos/electron/electron/issues/8099",
    "id": 266813181,
    "user": {
      "login": "dustinblackman",
      "id": 5246169,
      "avatar_url": "https://avatars0.githubusercontent.com/u/5246169?v=3",
      "gravatar_id": "",
      "url": "https://api.github.com/users/dustinblackman",
      "html_url": "https://github.com/dustinblackman",
      "followers_url": "https://api.github.com/users/dustinblackman/followers",
      "following_url": "https://api.github.com/users/dustinblackman/following{/other_user}",
      "gists_url": "https://api.github.com/users/dustinblackman/gists{/gist_id}",
      "starred_url": "https://api.github.com/users/dustinblackman/starred{/owner}{/repo}",
      "subscriptions_url": "https://api.github.com/users/dustinblackman/subscriptions",
      "organizations_url": "https://api.github.com/users/dustinblackman/orgs",
      "repos_url": "https://api.github.com/users/dustinblackman/repos",
      "events_url": "https://api.github.com/users/dustinblackman/events{/privacy}",
      "received_events_url": "https://api.github.com/users/dustinblackman/received_events",
      "type": "User",
      "site_admin": false
    },
    "created_at": "2016-12-13T18:00:53Z",
    "updated_at": "2016-12-13T18:02:16Z",
    "body": "You're right, it was throwing an exception but with no way of knowing when using `remote`, as the dev console tools log was empty. The exception was my application wasn't signed. I only found out by attempting the same logic within the index of my electron project, and seeing the error there. `after` is also never logged.\r\n\r\nI'll keep this open as the behaviour from remote doesn't seem optimal. Otherwise feel free to close. Thanks!"
  },
  {
    "url": "https://api.github.com/repos/electron/electron/issues/comments/266814590",
    "html_url": "https://github.com/electron/electron/issues/8099#issuecomment-266814590",
    "issue_url": "https://api.github.com/repos/electron/electron/issues/8099",
    "id": 266814590,
    "user": {
      "login": "kevinsawicki",
      "id": 671378,
      "avatar_url": "https://avatars0.githubusercontent.com/u/671378?v=3",
      "gravatar_id": "",
      "url": "https://api.github.com/users/kevinsawicki",
      "html_url": "https://github.com/kevinsawicki",
      "followers_url": "https://api.github.com/users/kevinsawicki/followers",
      "following_url": "https://api.github.com/users/kevinsawicki/following{/other_user}",
      "gists_url": "https://api.github.com/users/kevinsawicki/gists{/gist_id}",
      "starred_url": "https://api.github.com/users/kevinsawicki/starred{/owner}{/repo}",
      "subscriptions_url": "https://api.github.com/users/kevinsawicki/subscriptions",
      "organizations_url": "https://api.github.com/users/kevinsawicki/orgs",
      "repos_url": "https://api.github.com/users/kevinsawicki/repos",
      "events_url": "https://api.github.com/users/kevinsawicki/events{/privacy}",
      "received_events_url": "https://api.github.com/users/kevinsawicki/received_events",
      "type": "User",
      "site_admin": true
    },
    "created_at": "2016-12-13T18:06:09Z",
    "updated_at": "2016-12-13T18:06:09Z",
    "body": "> You're right, it was throwing an exception but with no way of knowing when using remote, as the dev console tools log was empty. \r\n\r\nDid your application have a `window.onerror` handler and/or `process.on('uncaughtexception')` handler? It would be great to know more in case there is an issue in the `remote` module. Only uncaught errors or explicitly logged errors (`console.error`) go to the dev tools."
  },
  {
    "url": "https://api.github.com/repos/electron/electron/issues/comments/266816963",
    "html_url": "https://github.com/electron/electron/issues/8099#issuecomment-266816963",
    "issue_url": "https://api.github.com/repos/electron/electron/issues/8099",
    "id": 266816963,
    "user": {
      "login": "dustinblackman",
      "id": 5246169,
      "avatar_url": "https://avatars0.githubusercontent.com/u/5246169?v=3",
      "gravatar_id": "",
      "url": "https://api.github.com/users/dustinblackman",
      "html_url": "https://github.com/dustinblackman",
      "followers_url": "https://api.github.com/users/dustinblackman/followers",
      "following_url": "https://api.github.com/users/dustinblackman/following{/other_user}",
      "gists_url": "https://api.github.com/users/dustinblackman/gists{/gist_id}",
      "starred_url": "https://api.github.com/users/dustinblackman/starred{/owner}{/repo}",
      "subscriptions_url": "https://api.github.com/users/dustinblackman/subscriptions",
      "organizations_url": "https://api.github.com/users/dustinblackman/orgs",
      "repos_url": "https://api.github.com/users/dustinblackman/repos",
      "events_url": "https://api.github.com/users/dustinblackman/events{/privacy}",
      "received_events_url": "https://api.github.com/users/dustinblackman/received_events",
      "type": "User",
      "site_admin": false
    },
    "created_at": "2016-12-13T18:15:17Z",
    "updated_at": "2016-12-13T18:17:02Z",
    "body": "Ah you're right. I'm using winston and it has a uncaught exception handler, and wasn't properly passing the error to logs (dev tools or log file). With it disabled, error ended up in the dev tools just fine. Good catch, thanks for the help. "
  }
]